Workbook

Sheet עוגני קריירה
L2: שם:
C5: שלב א': עד כמה נכון כל אחד מהמשפטים הבאים לגביך? סמן את המספר המתאים משמאלו של כל משפט!
D6: נכון לחלוטין | F6: נכון במידה בינונית | I6: לא נכון בכלל
D7: 6 | E7: 5 | F7: 4 | G7: 3 | H7: 2 | I7: 1
L8: שלב א' | M8: שלב ב'
B10: .1 | C10: אני רוצה להגיע לדרגת מומחיות כה גבוהה שעצותיי יהיו תמיד מצרך מבוקש ביותר | L10: 4 | Q10: נכון ביותר לגבי
B11: .2 | C11: אני חש שאני מממש את עצמי בעבודה כאשר אני מצליח לנהל אחרים ואת עבודתם | L11: 5 | P11: 6
B12: .3 | C12: אני חולם על קריירה שתאפשר לי יד חופשית ואוטונומיה במילוי תפקידי השונים. | L12: 4 | P12: 5
B13: .4 | C13: קביעות ויציבות חשובים לי יותר מאשר חופש ועצמאות | L13: 5 | P13: 4
B14: .5 | C14: אני מחפש תמיד רעיונות שיאפשרו לי לבנות עסק משלי | L14: 5 | P14: 3
B15: .6 | C15: אחוש הצלחה בקריירה רק אם ארגיש שתרמתי משהו משמעותי לרווחת החברה בה אני חי | L15: 5 | P15: 2
B16: .7 | C16: אני חולם על קריירה שתאפשר לי לפתור בהצלחה בעיות במצבים מורכבים במיוחד | L16: 5 | P16: 1
B17: .8 | C17: אבחר לעזוב את הארגון, אם יציבו אותי בתפקיד שיצמצם את יכולתי להתמיד בפעילויות משפחה ופנאי | L17: 4
B18: .9 | C18: אחוש הצלחה בקריירה, רק אם יתאפשר לי לפתח את כישורי המקצועיים לרמה גבוהה ביותר | L18: 4
B19: .10 | C19: הייתי רוצה לנהל ארגון גדול ומורכב ולקבל החלטות שישפיעו על אנשים רבים | L19: 4
B20: .11 | C20: אני חש שהגעתי למימוש עצמי, בעיקר כאשר מתאפשר לי להגדיר את המטלות, לוח הזמנים והמהלכים במסגרת תפקידי. | L20: 5
B21: .12 | C21: אבחר לעזוב את הארגון, אם אקבל תפקיד שיסכן את הסיכוי שלי לקביעות בארגון. | L21: 4
B22: .13 | C22: הקמת עסק משלי חשובה לי יותר מתפקיד ניהולי בכיר בארגון השייך לאחרים | L22: 4
B23: .14 | C23: אני חש שהגעתי למימוש עצמי בקריירה, כאשר מתאפשר לי לתרום מכישורי לטובת אחרים. | L23: 5
B24: .15 | C24: אחוש הצלחה בקריירה, אם אתמודד בהצלחה עם אתגרים קשים ואצליח להתגבר עליהם | L24: 5
B25: .16 | C25: אני חולם על קריירה שתאפשר לי לשלב את צרכיי האישיים, צרכי המשפחה וצרכי עבודה | L25: 5
B26: .17 | C26: מושך אותי יותר למלא תפקיד מקצועי בכיר בתחום התמחותי מאשר תפקיד מנכ"ל | L26: 5
B27: .18 | C27: אחוש הצלחה בקריירה, רק אם אהיה מנכ"ל בארגון | L27: 4
B28: .19 | C28: אחוש הצלחה בקריירה, רק אם יהיו לי חופש ועצמאות מלאים | L28: 4
... B32: .23 | C32: אני חש שהגעתי למימוש עצמי, בעקר כאשר אני פותר בעיות שנראו לא פתורות או חסרות סיכויים | L32: 5
B33: .24 | C33: אחוש הצלחה בחיי, רק אם אהיה מסוגל לאזן בין צרכי האישיים, צרכי המשפחה וצרכי הקריירה שלי | L33: 5 | M33: נכון ביותר לגבי
B34: .25 | C34: אעדיף לעזוב את הארגון אם יציבו אותי לתפקיד שאינו בתחום ההתמחות שלי | L34: 4
B35: .26 | C35: מושך אותי יותר תפקיד מנכ"ל מאשר תפקיד ניהולי בכיר בתחום ההתמחות המקצועי שלי | L35: 4
B36: .27 | C36: האפשרות למלא תפקיד בדרכי, ללא נהלים ומגבלות חשובה לי יותר מביטחון תעסוקתי | L36: 5
B37: .28 | C37: אני חש שהגעתי למימוש עצמי, בעיקר כאשר אני משיג בטחון כלכלי ותעסוקתי | L37: 4
B38: .29 | C38: אחוש הצלחה בקריירה, רק אם אצליח ליצור או לבנות משהו שהוא כולו רעיון שלי ומוצר שלי | L38: 4
B39: .30 | C39: אני חולם על קריירה שתהיה בה תרומה ממשית לחברה ולאנושות | L39: 5 | M39: נכון ביותר לגבי
B40: .31 | C40: אני מחפש בעבודה הזדמנויות לבטא את כישורי התחרותיים ו/או יכולתי לפתור בעיות | L40: 4
B41: .32 | C41: חשוב לי יותר האיזון בין דרישות מחיי העבודה ודרישות מחיי האישיים לעומת הסיכוי להשיג תפקיד ניהולי בכיר | L41: 5
B42: .33 | C42: אני חש שהגעתי למימוש עצמי, בעקר כאשר אני משתמש ביכולתי וכישורי המיוחדים | L42: 5 | M42: נכון ביותר לגבי
B43: .34 | C43: אבחר לעזוב את הארגון, אם לא יהיה לי סיכוי להתקדם במסלול הניהול הכללי | L43: 5
B44: .35 | C44: אעדיף לעזוב את הארגון שלי, אם אוצב לתפקיד שיקטין את העצמאות וחופש הפעולה שלי | L44: 5
B45: .36 | C45: אני חולם על קריירה שתאפשר לי תחושת בטחון ויציבות | L45: 4
B46: .37 | C46: אני חולם על הקמת עסק משלי | L46: 5
B47: .38 | C47: אעדיף לעזוב את הארגון, אם אוצב לתפקיד שיקטין את יכולתי להעניק שרות לאחרים | L47: 4
...

Sheet סיכום
G1: מצאי אוריינטציות בקריירה
Q2: שם: | R2: =IF('עוגני קריירה'!L3="","",'עוגני קריירה'!L3)
C6: TF | E6: GM | G6: AU | I6: SE | K6: EC | M6: SV | O6: CH | Q6: LS
C7: 1 | D7: ='חישוב ביניים'!E3 -> 4 | E7: 2 | F7: ='חישוב ביניים'!E4 -> 5 | G7: 3 | H7: ='חישוב ביניים'!E5 -> 4 | I7: 4 | J7: ='חישוב ביניים'!E6 -> 5 | K7: 5 | L7: ='חישוב ביניים'!E7 -> 5 | M7: 6 | N7: ='חישוב ביניים'!E8 -> 5 | O7: 7 | P7: ='חישוב ביניים'!E9 -> 5 | Q7: 8 | R7: ='חישוב ביניים'!E10 -> 4
C8: 9 | D8: ='חישוב ביניים'!E11 -> 4 | E8: 10 | F8: ='חישוב ביניים'!E12 -> 4 | G8: 11 | H8: ='חישוב ביניים'!E13 -> 5 | I8: 12 | J8: ='חישוב ביניים'!E14 -> 4 | K8: 13 | L8: ='חישוב ביניים'!E15 -> 4 | M8: 14 | N8: ='חישוב ביניים'!E16 -> 5 | O8: 15 | P8: ='חישוב ביניים'!E17 -> 5 | Q8: 16 | R8: ='חישוב ביניים'!E18 -> 5
C9: 17 | D9: ='חישוב ביניים'!E19 -> 5 | E9: 18 | F9: ='חישוב ביניים'!E20 -> 4 | G9: 19 | H9: ='חישוב ביניים'!E21 -> 4 | I9: 20 | J9: ='חישוב ביניים'!E22 -> 5 | K9: 21 | L9: ='חישוב ביניים'!E23 -> 4 | M9: 22 | N9: ='חישוב ביניים'!E24 -> 5 | O9: 23 | P9: ='חישוב ביניים'!E25 -> 5 | Q9: 24 | R9: ='חישוב ביניים'!E26 -> 9
C10: 25 | D10: ='חישוב ביניים'!E27 -> 4 | E10: 26 | F10: ='חישוב ביניים'!E28 -> 4 | G10: 27 | H10: ='חישוב ביניים'!E29 -> 5 | I10: 28 | J10: ='חישוב ביניים'!E30 -> 4 | K10: 29 | L10: ='חישוב ביניים'!E31 -> 4 | M10: 30 | N10: ='חישוב ביניים'!E32 -> 9 | O10: 31 | P10: ='חישוב ביניים'!E33 -> 4 | Q10: 32 | R10: ='חישוב ביניים'!E34 -> 5
C11: 33 | D11: ='חישוב ביניים'!E35 -> 9 | E11: 34 | F11: ='חישוב ביניים'!E36 -> 5 | G11: 35 | H11: ='חישוב ביניים'!E37 -> 5 | I11: 36 | J11: ='חישוב ביניים'!E38 -> 4 | K11: 37 | L11: ='חישוב ביניים'!E39 -> 5 | M11: 38 | N11: ='חישוב ביניים'!E40 -> 4 | O11: 39 | P11: ='חישוב ביניים'!E41 -> 4 | Q11: 40 | R11: ='חישוב ביניים'!E42 -> 4
B12: סה"כ | D12: =SUM(D7:D11) -> 26 | F12: =SUM(F7:F11) -> 22 | H12: =SUM(H7:H11) -> 23 | J12: =SUM(J7:J11) -> 22 | L12: =SUM(L7:L11) -> 22 | N12: =SUM(N7:N11) -> 28 | P12: =SUM(P7:P11) -> 23 | R12: =SUM(R7:R11) -> 27
B13: ממוצע | D13: =D12/5 -> 5.2 | F13: =F12/5 -> 4.4 | H13: =H12/5 -> 4.6 | J13: =J12/5 -> 4.4 | L13: =L12/5 -> 4.4 | N13: =N12/5 -> 5.6 | P13: =P12/5 -> 4.6 | R13: =R12/5 -> 5.4
B16: הנחיות לעיבוד שאלון אוריינטצית הקריירה - אדגר שיין: 1. הציונים המתקבלים משקפים את היררכיית הצרכים והערכים האישית שלי בקריירה מהגבוה לנמוך. במילים אחרות מה מאוד חשוב לי לממש בקריירה כאשר הממוצע לעוגן נע בין 4-8.4 וממה עדיף שאמנע – כאשר הממוצע לעוגן הקריירה הוא בין 1-2. 2. כדאי להתייחס לשניים עד שלושת העוגנים הגבוהים ביותר ולוודא שהם כלולים בתפקידים אותם אתם בוחרים כך תחושו שאתם מממשים את עצמכם, תחושו סיפוק וסקרנות להתמיד בעיסוק. כמו כן, כדאי להמנע מאלו שקיבלתם בהם ציונים נמוכים מאוד – אם הם יהיו דומיננטיים בתפקיד תחושו קושי, חוסר סיפוק ואי הצלחה לאורך זמן. * להעמקת הניתוח והמסקנות מומלץ לפנות ליועץ האישי שלך.
B27: מודל עוגני קריירה – איפיון 8 העוגנים:

Sheet חישוב ביניים
B2: משפט | C2: ציון ראשון | D2: תוספת | E2: ציון משוקלל
B3: 1 | C3: ='עוגני קריירה'!L10 -> 4 | D3: =IF('עוגני קריירה'!M10="נכון ביותר לגבי",4,0) -> 0 | E3: =C3+D3 -> 4 | F3: TF
B4: 2 | C4: ='עוגני קריירה'!L11 -> 5 | D4: =IF('עוגני קריירה'!M11="נכון ביותר לגבי",4,0) -> 0 | E4: =C4+D4 -> 5 | F4: GM
B5: 3 | C5: ='עוגני קריירה'!L12 -> 4 | D5: =IF('עוגני קריירה'!M12="נכון ביותר לגבי",4,0) -> 0 | E5: =C5+D5 -> 4 | F5: AU
B6: 4 | C6: ='עוגני קריירה'!L13 -> 5 | D6: =IF('עוגני קריירה'!M13="נכון ביותר לגבי",4,0) -> 0 | E6: =C6+D6 -> 5 | F6: SE
B7: 5 | C7: ='עוגני קריירה'!L14 -> 5 | D7: =IF('עוגני קריירה'!M14="נכון ביותר לגבי",4,0) -> 0 | E7: =C7+D7 -> 5 | F7: EC
B8: 6 | C8: ='עוגני קריירה'!L15 -> 5 | D8: =IF('עוגני קריירה'!M15="נכון ביותר לגבי",4,0) -> 0 | E8: =C8+D8 -> 5 | F8: SV
B9: 7 | C9: ='עוגני קריירה'!L16 -> 5 | D9: =IF('עוגני קריירה'!M16="נכון ביותר לגבי",4,0) -> 0 | E9: =C9+D9 -> 5 | F9: CH
B10: 8 | C10: ='עוגני קריירה'!L17 -> 4 | D10: =IF('עוגני קריירה'!M17="נכון ביותר לגבי",4,0) -> 0 | E10: =C10+D10 -> 4 | F10: LS
B11: 9 | C11: ='עוגני קריירה'!L18 -> 4 | D11: =IF('עוגני קריירה'!M18="נכון ביותר לגבי",4,0) -> 0 | E11: =C11+D11 -> 4 | F11: TF
B12: 10 | C12: ='עוגני קריירה'!L19 -> 4 | D12: =IF('עוגני קריירה'!M19="נכון ביותר לגבי",4,0) -> 0 | E12: =C12+D12 -> 4 | F12: GM
B13: 11 | C13: ='עוגני קריירה'!L20 -> 5 | D13: =IF('עוגני קריירה'!M20="נכון ביותר לגבי",4,0) -> 0 | E13: =C13+D13 -> 5 | F13: AU
B14: 12 | C14: ='עוגני קריירה'!L21 -> 4 | D14: =IF('עוגני קריירה'!M21="נכון ביותר לגבי",4,0) -> 0 | E14: =C14+D14 -> 4 | F14: SE
... B42: 40 | C42: ='עוגני קריירה'!L49 -> 4 | D42: =IF('עוגני קריירה'!M49="נכון ביותר לגבי",4,0) -> 0 | E42: =C42+D42 -> 4 | F42: LS
