Workbook

Sheet פעילויות
B3: חלק I - פעילויות
B5: סמן X במשבצת של "כן" ליד פעילויות שהנך אוהב לעשות, או שהיית רוצה ללמוד לעשותן סמן X במשבצת של "לא" ליד פעילויות שאינך אוהב לעשות או שאין לך כל יחס אליהן ואין לך עניין ללמוד לעשותן
B7: פעילויות "ביצוע" R | F7: כן | G7: לא | J7: פעילויות "חברתיות" S | K7: כן | L7: לא
B8: לתקן מכשירים בבית | J8: לעבוד כחלק מעבודת צוות
B9: לתכנן ולעצב חדרים ובתים | J9: להשתתף בפעילויות קהילתיות
B10: לתקן ולשפץ חפצים ורהיטים | J10: להשתייך לקבוצות חברתיות או לקהילה
B11: לבנות מודלים מעץ, מפלסטיק או מקרטון | J11: לעזור לאנשים בבעיותיהם האישיות
B12: להשתמש בכלי עבודה- מקדחה, מברגה, מסור וכו' | J12: לטפל ולעזור לנוער
B13: לטפל במכונית או באופנוע | J13: להשתתף במסיבות, כנסים ואירועים חברתיים
B14: לבשל ולאפות | J14: ללמוד קורסים בתחום משאבי אנוש ומדעי החברה
B15: להשתתף בקורס לשרטוט מכני | J15: ללמוד תיאוריות ומודלים פסיכולוגיים
B16: להשתתף בקורס נגרות או עבודות עץ | J16: להסביר ולהדריך אחרים
B17: להשתתף בקורס מלאכה | J17: להכיר אנשים חדשים
E18: סה"כ תשובות "כן" >> | F18: =COUNTA(F8:F17) -> 0 | J18: סה"כ תשובות "כן" >> | K18: =COUNTA(K8:K17) -> 0
B20: פעילויות "חקרניות" I | F20: כן | G20: לא | J20: פעילויות "יוזמה" E | K20: כן | L20: לא
B21: לקרוא ספרים, מאמרים או כתבי-עת מדעיים | J21: להשפיע על אחרים
B22: לעבוד במעבדה | J22: להשתתף בתהליכי מו"מ
B23: לעסוק במחקר מדעי | J23: להפעיל שרות או עסק עצמאי
B24: להשתתף בכנסי מדע ומחקר | J24: להשתתף בכנסי עסקים
B25: לחקור וללמוד את מדעי המחשב | J25: להרצות
B26: לפתור בעיות מתמטיות | J26: לנהל ולהנחות אחרים
B27: להשתתף בקורס בפיסיקה או כימה | J27: להדריך ולחנוך עובדים
B28: לחקור תרבויות וביוגרפיות של אנשים | J28: לפגוש אנשים חשובים
B29: ללמוד על מדעי המוח | J29: להנהיג קבוצה לקראת ביצוע מטרה מסויימת
B30: לחקור את הכוכבים והחלל | J30: ליזום רעיונות לעסקים
E31: סה"כ תשובות "כן" >> | F31: =COUNTA(F21:F30) -> 0 | J31: סה"כ תשובות "כן" >> | K31: =COUNTA(K21:K30) -> 0
B33: פעילות "אומנותיות" A | F33: כן | G33: לא | J33: פעילות "מנהליות" C | K33: כן | L33: לא
B34: לרשום, לצייר או לצבוע | J34: לעסוק בפעולות של ארגון וסידור
B35: לעסוק בעיצוב גרפי או חזותי | J35: לעשות פעולות חשבון בעסקים או בהנה"ח
B36: לנגן או לשיר בלהקה, בקבוצה או בתזמורת | J36: להפעיל תכונות חישוב כמו אקסל
B37: לנגן על כלי נגינה | J37: לנהל רישום ותיעוד מפורט של מידע ונתונים
B38: ללכת להופעות, קונצרטים או הצגות | J38: להשתתף בקורס סטטיסטיקה
B39: לעסוק בעיצוב פנים או בעיצוב אופנה | J39: להשתתף בקורס להנהלת חשבונות, מיסוי, רגולציה וכד'
B40: להשתתף בחוג ריקוד או בלהקה | J40: לתכנן ולבנות תכניות עבודה מפורטות
B41: לעסוק בצילום | J41: לארגן ולסדר מסמכים ודו"חות
B42: לכתוב שירה או סיפורים | J42: לכתוב מסמכים או מכתבים עסקיים
B43: להשתתף בשיעורי אומנות | J43: לנתח ולעבד נתונים
E44: סה"כ תשובות "כן" >> | F44: =COUNTA(F34:F43) -> 0 | J44: סה"כ תשובות "כן" >> | K44: =COUNTA(K34:K43) -> 0

Sheet כישורים
B3: חלק II - יכולות
B5: סמן X במשבצת של "כן" ליד פעילויות שהנך יכול לעשות טוב או במומחיות סמן X במשבצת של "לא" ליד פעילויות שמעולם לא ביצעת אותן, או שביצעת אותן ללא הצלחה
B7: כשרי "ביצוע" R | F7: כן | G7: לא | J7: כשרים "חברתיים" S | K7: כן | L7: לא
B8: אני יודע להשתמש בארגז כלים שכולל פטיש, מברגים, מסמרים וכו' | J8: השתתפתי בפעולות התנדבות
B9: אני יודע לתפור | J9: אני משתף פעולה ועובד היטב עם אנשים אחרים
B10: אני יודע להשתמש במכשירי עבודה כגון מקדחה חשמלית ומברגה | J10: אני מצליח ליזום שיחה ולעניין אנשים
B11: אני יודע לשפץ ולבנות רהיטים | J11: אני יודע להיות מארח טוב
B12: אני יודע להבין שרטוטים | J12: אני מצליח להסביר דברים לאחרים בצורה טובה
B13: אני יודע לעשות תיקונים פשוטים בבית | J13: אני מרבה לתקשר עם אנשים ברשתות החברתיות
B14: אני יודע לאפות ולבשל | J14: אני מסוגל לעזור לאנשים שנמצאים בצרה
B15: אני יודע לצבוע רהיטים או קירות | J15: עסקתי בהדרכה והנחיה
B16: אני יודע לפתור בעיות במחשב | J16: אני יודע לתכנן פעילות חברתית בעבודה או במסגרת אחרת
B17: יש לי הבנה טכנית | J17: אני מבין בצורה טובה את אישיותם של אחרים
E18: סה"כ תשובות "כן" >> | F18: =COUNTA(F8:F17) -> 0 | J18: סה"כ תשובות "כן" >> | K18: =COUNTA(K8:K17) -> 0
B20: כשרים "חקרניים" I | F20: כן | G20: לא | J20: כשרי "יוזמה" E | K20: כן | L20: לא
B21: אני מבין את העקרונות של האופן שבו עובדת הטלוויזיה | J21: נבחרתי לתפקיד יצוגי בתיכון, בעבודה או במקום אחר
B22: אני יכול לציין שמות של 5 מאכלים עשירים בחלבון | J22: אני יודע לפקח על עבודתם של אחרים
B23: אני צופה בסרטים ובתכניות על טבע ומדע | J23: יש לי הרבה מרץ והתלהבות
B24: אני מבין את העקרונות של שפת המחשב | J24: אני מצליח להניע ולהפעיל אנשים
B25: אני טוב בפתירת חידות ובעיות היגיון או חשבון | J25: אני "איש עסקים" טוב
B26: אני קורא מחקרים ומאמרים מדעיים | J26: שמשתי כדובר של קבוצה
B27: אני יודע להסביר את תפקיד כדוריות הדם הלבנות | J27: הפעלתי עסק או שירות עצמאי
B28: אני קורא הרבה ספרים | J28: ארגנתי קבוצה, מועדון או חבורה
B29: אני מבין מדוע לוויינים מלאכותיים אינם נופלים ארצה | J29: אני יכול להיות מנהיג או מנהל מוצלח
B30: השתתפתי בכנס מדעי או בתחרות מדעית | J30: אני טוב בשכנוע ובמשא ומתן
E31: סה"כ תשובות "כן" >> | F31: =COUNTA(F21:F30) -> 0 | J31: סה"כ תשובות "כן" >> | K31: =COUNTA(K21:K30) -> 0
B33: כישורים "אמנותיים" A | F33: כן | G33: לא | J33: כשרים "מנהליים" C | K33: כן | L33: לא
B34: אני יודע לנגן בכלי מוסיקלי | J34: אני יודע לתכנן לוח זמנים לפעולות מורכבות
B35: אני יכול להשתתף במקהלה או להקה | J35: אני יודע לארגן עבודת ניירת רבה בזמן קצר
B36: אני יכול לעצב תלבושות או בגדים | J36: אני יודע לארגן ולטפל במשימות מרובות פרטים ונתונים
B37: אני יכול לשחק בהצגה | J37: אני יודע למלא תפקיד של מזכיר או מנהל משרד
B38: אני יכול להופיע בערב קריאה | J38: אני יודע להשתמש בתוכנות להנהלת חשבונות
B39: אני יודע לרקוד | J39: אני יודע לתכנן ולארגן אירועים ופרויקטים
B40: אני יודע לצייר או לפסל | J40: אני יודע לנהל רשום מדויק של מכירות ותשלומים
B41: אני יודע ליצור מוצרי נוי או תכשיטים | J41: אני יודע לרשום פרוטוקול של ישיבה או אסיפה
B42: אני יודע לתכנן ולעצב במחשב | J42: אני יודע לעבוד עם אקסל או עם תוכנות אחרות של ניתוח נתונים
B43: אני יודע לכתוב סיפורים או שירים טובים | J43: אני יודע לערוך רישום מלאי מדויק
E44: סה"כ תשובות "כן" >> | F44: =COUNTA(F34:F43) -> 0 | J44: סה"כ תשובות "כן" >> | K44: =COUNTA(K34:K43) -> 0

Sheet עניין
B3: חלק III - מקצועות
B5: סמן X במשבצת של "כן" ליד מקצועות המעניינים או המושכים אותך סמן X במשבצת של "לא" ליד פעילויות שאינך מחבב או חושב אותם ללא מעניינים
B7: מקצועות "ביצועיים" R | F7: כן | G7: לא | J7: מקצועות "חברתיים" S | K7: כן | L7: לא
B8: טבח או שף | J8: מורה בבית ספר תיכון
B9: מהנדס בניין | J9: מדריך נוער
B10: טכנאי מטוסים | J10: קלינאי תקשורת
B11: מהנדס אזרחי | J11: אח בבית חולים או במוסד רפואי
B12: מטפל בחיות | J12: הדרכת הורים או יעוץ משפחתי
B13: מהנדס חשמל | J13: מנהל קהילות
B14: טכנאי ייצור | J14: פסיכולוג קליני או מטפל
B15: מהנדס אלקטרוניקה | J15: דיאטן או תזונאי
B16: סייבר | J16: הנחיית קבוצות
B17: מהנדס תעשיה וניהול | J17: עובד סוציאלי
B18: מתכנת | J18: יועץ תעסוקתי
B19: הנדסת מכונות | J19: שיקום ושילוב אנשים עם מוגבלות
... B21: מהנדס מוצר | J21: מרפא בעיסוק
B22: סה"כ תשובות "כן" >> | F22: =COUNTA(F8:F21) -> 0 | J22: סה"כ תשובות "כן" >> | K22: =COUNTA(K8:K21) -> 0
B24: מקצועות "חקרניים" I | F24: כן | G24: לא | J24: מקצועות "יוזמה" E | K24: כן | L24: לא
B25: ביו-טכנולוג | J25: יועץ ארגוני
B26: מתמטיקאי | J26: איש עסקים
B27: חוקר חלל ותעופה | J27: יזם חברה או סטארט-אפ
B28: אנתרופולוג וחוקר תרבויות | J28: מפיק בטלוויזיה
B29: היסטוריון | J29: מנהל מלון או מסעדה
B30: כימאי | J30: מנהל עסק
B31: כתיבה מדעית | J31: עורך דין
B32: כותב מאמרים מדעיים | J32: פרסומאי
B33: מנהל מעבדה | J33: יועץ לפיתוח עסקי ואסטרטגי
B34: וטרינר | J34: סוכן נדל"ן
B35: רופא | J35: מנהל הפקה
B36: פיסיקאי | J36: יועץ תקשורת או דובר
... B38: מפתח R&D | J38: מנהל בכיר בחברה גדולה
B39: סה"כ תשובות "כן" >> | F39: =COUNTA(F25:F38) -> 0 | J39: סה"כ תשובות "כן" >> | K39: =COUNTA(K25:K38) -> 0
B41: מקצועות "אמנותיים" A | F41: כן | G41: לא | J41: מקצועות "מנהליים" C | K41: כן | L41: לא
B42: משורר או סופר | J42: מנהל חשבונות
B43: מעצב פנים | J43: מנהל למידה
B44: מוסיקאי | J44: תקציבאי
B45: אדריכל | J45: מנהל כספים
B46: גרפיקאי | J46: דאטה אנליסט
B47: צלם קולנוע | J47: עובד בנק
B48: מעצב אתרים UX/UI | J48: מנהל אגף במשרד ממשלתי
...

Sheet סיכום
B3: חלק VI - סיכום
E7: C | F7: E | G7: S | H7: A | I7: I | J7: R
B9: פעילויות | E9: =פעילויות!K44 -> 0 | F9: =פעילויות!K31 -> 0 | G9: =פעילויות!K18 -> 0 | H9: =פעילויות!F44 -> 0 | I9: =פעילויות!F31 -> 0 | J9: =פעילויות!F18 -> 0
B11: כישורים | E11: =כישורים!K44 -> 0 | F11: =כישורים!K31 -> 0 | G11: =כישורים!K18 -> 0 | H11: =כישורים!F44 -> 0 | I11: =כישורים!F31 -> 0 | J11: =כישורים!F18 -> 0
B13: מקצועות | E13: =עניין!K54 -> 0 | F13: =עניין!K39 -> 0 | G13: =עניין!K22 -> 0 | H13: =עניין!F54 -> 0 | I13: =עניין!F39 -> 0 | J13: =עניין!F22 -> 0
B15: סה"כ | E15: =SUM(E9:E14) -> 0 | F15: =SUM(F9:F14) -> 0 | G15: =SUM(G9:G14) -> 0 | H15: =SUM(H9:H14) -> 0 | I15: =SUM(I9:I14) -> 0 | J15: =SUM(J9:J14) -> 0
B18: הנחיות לעיבוד השאלון: טיפוסי האישיות - הולנד
B19: קיימים שישה טיפוסי אישיות, על מנת לאתר את טיפוסי האישיות המאפיינים אותך עליך להתייחס לשניים עד שלושת הטיפוסים שקיבלו ציונים גבוהים ביותר בשורת הסיכום בטבלה.
B20: שלושת הטיפוסים הללו מבטאים את מוקדי העניין שלך בקריירה וגורמי ההנעה שלך וכמו כן מצביעים על אופי העיסוק אשר יסב לך סיפוק והנאה.
B21: הטיפוסים שקיבלו ציונים נמוכים ביותר - מצביעים על אופי עיסוקים שלא יעניינו אותך כלל ואף יגרום לך לחוש חוסר יכולת בהתמודדות עם סוג כזה של תפקידים.
B22: סמנו את שלושת הטיפוסים שקיבלו ציונים גבוהים ביותר.
B25: מאפייני טיפוסים:
